2020-09-21 20:51:59,490 INFO: Lang startup [in C:\Users\1\web_app1\app\__init__.py:33]
2020-09-21 21:07:58,359 INFO: Lang startup [in C:\Users\1\web_app1\app\__init__.py:33]
2020-09-21 21:11:00,734 INFO: Lang startup [in C:\Users\1\web_app1\app\__init__.py:33]
2020-09-21 21:11:39,053 INFO: Lang startup [in C:\Users\1\web_app1\app\__init__.py:33]
2020-09-21 21:18:54,111 INFO: Lang startup [in C:\Users\1\web_app1\app\__init__.py:33]
2020-09-21 21:21:24,402 INFO: Lang startup [in C:\Users\1\web_app1\app\__init__.py:33]
2020-09-21 21:22:50,950 INFO: Lang startup [in C:\Users\1\web_app1\app\__init__.py:33]
2020-09-21 21:28:03,253 INFO: Lang startup [in C:\Users\1\web_app1\app\__init__.py:33]
2020-09-21 21:44:23,678 INFO: Lang startup [in C:\Users\1\web_app1\app\__init__.py:33]
2020-09-21 21:44:28,390 ERROR: Exception on /mywords [GET] [in c:\users\1\web_app1\venv\lib\site-packages\flask\app.py:1891]
Traceback (most recent call last):
  File "c:\users\1\web_app1\venv\lib\site-packages\flask\app.py", line 2447, in wsgi_app
    response = self.full_dispatch_request()
  File "c:\users\1\web_app1\venv\lib\site-packages\flask\app.py", line 1952, in full_dispatch_request
    rv = self.handle_user_exception(e)
  File "c:\users\1\web_app1\venv\lib\site-packages\flask\app.py", line 1821, in handle_user_exception
    reraise(exc_type, exc_value, tb)
  File "c:\users\1\web_app1\venv\lib\site-packages\flask\_compat.py", line 39, in reraise
    raise value
  File "c:\users\1\web_app1\venv\lib\site-packages\flask\app.py", line 1950, in full_dispatch_request
    rv = self.dispatch_request()
  File "c:\users\1\web_app1\venv\lib\site-packages\flask\app.py", line 1936, in dispatch_request
    return self.view_functions[rule.endpoint](**req.view_args)
  File "c:\users\1\web_app1\venv\lib\site-packages\flask_login\utils.py", line 272, in decorated_view
    return func(*args, **kwargs)
  File "C:\Users\1\web_app1\app\routes.py", line 105, in get_mywords
    words = current_user.languages[language.id].words.paginate(
AttributeError: 'NoneType' object has no attribute 'id'
2020-09-21 21:46:25,511 INFO: Lang startup [in C:\Users\1\web_app1\app\__init__.py:33]
2020-09-21 21:46:27,289 ERROR: Exception on /mywords [GET] [in c:\users\1\web_app1\venv\lib\site-packages\flask\app.py:1891]
Traceback (most recent call last):
  File "c:\users\1\web_app1\venv\lib\site-packages\flask\app.py", line 2447, in wsgi_app
    response = self.full_dispatch_request()
  File "c:\users\1\web_app1\venv\lib\site-packages\flask\app.py", line 1952, in full_dispatch_request
    rv = self.handle_user_exception(e)
  File "c:\users\1\web_app1\venv\lib\site-packages\flask\app.py", line 1821, in handle_user_exception
    reraise(exc_type, exc_value, tb)
  File "c:\users\1\web_app1\venv\lib\site-packages\flask\_compat.py", line 39, in reraise
    raise value
  File "c:\users\1\web_app1\venv\lib\site-packages\flask\app.py", line 1950, in full_dispatch_request
    rv = self.dispatch_request()
  File "c:\users\1\web_app1\venv\lib\site-packages\flask\app.py", line 1936, in dispatch_request
    return self.view_functions[rule.endpoint](**req.view_args)
  File "c:\users\1\web_app1\venv\lib\site-packages\flask_login\utils.py", line 272, in decorated_view
    return func(*args, **kwargs)
  File "C:\Users\1\web_app1\app\routes.py", line 106, in get_mywords
    page, application.config['Words'], False)
KeyError: 'Words'
2020-09-21 21:47:09,324 INFO: Lang startup [in C:\Users\1\web_app1\app\__init__.py:33]
2020-09-21 21:47:21,477 INFO: Lang startup [in C:\Users\1\web_app1\app\__init__.py:33]
2020-09-21 21:47:23,185 ERROR: Exception on /mywords [GET] [in c:\users\1\web_app1\venv\lib\site-packages\flask\app.py:1891]
Traceback (most recent call last):
  File "c:\users\1\web_app1\venv\lib\site-packages\flask\app.py", line 2447, in wsgi_app
    response = self.full_dispatch_request()
  File "c:\users\1\web_app1\venv\lib\site-packages\flask\app.py", line 1952, in full_dispatch_request
    rv = self.handle_user_exception(e)
  File "c:\users\1\web_app1\venv\lib\site-packages\flask\app.py", line 1821, in handle_user_exception
    reraise(exc_type, exc_value, tb)
  File "c:\users\1\web_app1\venv\lib\site-packages\flask\_compat.py", line 39, in reraise
    raise value
  File "c:\users\1\web_app1\venv\lib\site-packages\flask\app.py", line 1950, in full_dispatch_request
    rv = self.dispatch_request()
  File "c:\users\1\web_app1\venv\lib\site-packages\flask\app.py", line 1936, in dispatch_request
    return self.view_functions[rule.endpoint](**req.view_args)
  File "c:\users\1\web_app1\venv\lib\site-packages\flask_login\utils.py", line 272, in decorated_view
    return func(*args, **kwargs)
  File "C:\Users\1\web_app1\app\routes.py", line 106, in get_mywords
    page, application.config['WORDS_PER_PAGS'], False)
KeyError: 'WORDS_PER_PAGS'
2020-09-21 21:47:31,864 INFO: Lang startup [in C:\Users\1\web_app1\app\__init__.py:33]
2020-09-21 21:47:33,370 ERROR: Exception on /mywords [GET] [in c:\users\1\web_app1\venv\lib\site-packages\flask\app.py:1891]
Traceback (most recent call last):
  File "c:\users\1\web_app1\venv\lib\site-packages\flask\app.py", line 2447, in wsgi_app
    response = self.full_dispatch_request()
  File "c:\users\1\web_app1\venv\lib\site-packages\flask\app.py", line 1952, in full_dispatch_request
    rv = self.handle_user_exception(e)
  File "c:\users\1\web_app1\venv\lib\site-packages\flask\app.py", line 1821, in handle_user_exception
    reraise(exc_type, exc_value, tb)
  File "c:\users\1\web_app1\venv\lib\site-packages\flask\_compat.py", line 39, in reraise
    raise value
  File "c:\users\1\web_app1\venv\lib\site-packages\flask\app.py", line 1950, in full_dispatch_request
    rv = self.dispatch_request()
  File "c:\users\1\web_app1\venv\lib\site-packages\flask\app.py", line 1936, in dispatch_request
    return self.view_functions[rule.endpoint](**req.view_args)
  File "c:\users\1\web_app1\venv\lib\site-packages\flask_login\utils.py", line 272, in decorated_view
    return func(*args, **kwargs)
  File "C:\Users\1\web_app1\app\routes.py", line 112, in get_mywords
    return render_template('mywords.html', title='Dictionary', words = words.items, next_url = next_url, previous_url = prev_url, form=dictionaryForm)
NameError: name 'prev_url' is not defined
2020-09-21 21:48:01,249 INFO: Lang startup [in C:\Users\1\web_app1\app\__init__.py:33]
2020-09-21 22:15:38,752 INFO: Lang startup [in C:\Users\1\web_app1\app\__init__.py:33]
2020-09-21 22:19:31,905 INFO: Lang startup [in C:\Users\1\web_app1\app\__init__.py:33]
2020-09-21 22:43:51,788 INFO: Lang startup [in C:\Users\1\web_app1\app\__init__.py:33]
2020-09-21 22:43:58,150 ERROR: Exception on /index [GET] [in c:\users\1\web_app1\venv\lib\site-packages\flask\app.py:1891]
Traceback (most recent call last):
  File "c:\users\1\web_app1\venv\lib\site-packages\flask\app.py", line 2447, in wsgi_app
    response = self.full_dispatch_request()
  File "c:\users\1\web_app1\venv\lib\site-packages\flask\app.py", line 1952, in full_dispatch_request
    rv = self.handle_user_exception(e)
  File "c:\users\1\web_app1\venv\lib\site-packages\flask\app.py", line 1821, in handle_user_exception
    reraise(exc_type, exc_value, tb)
  File "c:\users\1\web_app1\venv\lib\site-packages\flask\_compat.py", line 39, in reraise
    raise value
  File "c:\users\1\web_app1\venv\lib\site-packages\flask\app.py", line 1950, in full_dispatch_request
    rv = self.dispatch_request()
  File "c:\users\1\web_app1\venv\lib\site-packages\flask\app.py", line 1936, in dispatch_request
    return self.view_functions[rule.endpoint](**req.view_args)
  File "c:\users\1\web_app1\venv\lib\site-packages\flask_login\utils.py", line 272, in decorated_view
    return func(*args, **kwargs)
  File "C:\Users\1\web_app1\app\routes.py", line 18, in index
    newsapi = NEWSAPI.get_top_headlines(language=form.languages.data, category=form.topic.data)
NameError: name 'NEWSAPI' is not defined
2020-09-21 22:44:27,228 INFO: Lang startup [in C:\Users\1\web_app1\app\__init__.py:33]
2020-09-21 22:44:31,520 ERROR: Exception on /index [GET] [in c:\users\1\web_app1\venv\lib\site-packages\flask\app.py:1891]
Traceback (most recent call last):
  File "c:\users\1\web_app1\venv\lib\site-packages\flask\app.py", line 2447, in wsgi_app
    response = self.full_dispatch_request()
  File "c:\users\1\web_app1\venv\lib\site-packages\flask\app.py", line 1952, in full_dispatch_request
    rv = self.handle_user_exception(e)
  File "c:\users\1\web_app1\venv\lib\site-packages\flask\app.py", line 1821, in handle_user_exception
    reraise(exc_type, exc_value, tb)
  File "c:\users\1\web_app1\venv\lib\site-packages\flask\_compat.py", line 39, in reraise
    raise value
  File "c:\users\1\web_app1\venv\lib\site-packages\flask\app.py", line 1950, in full_dispatch_request
    rv = self.dispatch_request()
  File "c:\users\1\web_app1\venv\lib\site-packages\flask\app.py", line 1936, in dispatch_request
    return self.view_functions[rule.endpoint](**req.view_args)
  File "c:\users\1\web_app1\venv\lib\site-packages\flask_login\utils.py", line 272, in decorated_view
    return func(*args, **kwargs)
  File "C:\Users\1\web_app1\app\routes.py", line 15, in index
    newsapi = app.config['NEWSAPI']
NameError: name 'app' is not defined
2020-09-21 22:45:04,038 INFO: Lang startup [in C:\Users\1\web_app1\app\__init__.py:33]
